from core.exceptions.base import CoreError


class RetryError(CoreError):
    pass
